<?xml version="1.0" ?>
<!-- =================================================================================== -->
<!-- |    This document was autogenerated by xacro from /home/cheney/24EME_FYP/src/myur_description/urdf/myur5.urdf.xacro | -->
<!-- |    EDITING THIS FILE BY HAND IS NOT RECOMMENDED                                 | -->
<!-- =================================================================================== -->
<robot name="myur5">
    <link name="booksink_link">
        <inertial>
            <origin rpy="0 0 0" xyz="0 0 0.28457334883271" />
            <mass value="41.6884762061747" />
            <inertia ixx="2.62451743594391" ixy="-0.589704408483634" ixz="-0.000559520034314575" iyy="3.12172134247769" iyz="-2.18230871282791E-06" izz="2.98496788067529" />
        </inertial>
        <visual>
            <origin rpy="0 0 0" xyz="0 0 0" />
            <geometry>
                <mesh filename="package://booksink/meshes/booksink_link.STL" />
            </geometry>
            <surface>
		<friction>
		   <ode>
		      <mu>100</mu>
		      <mu2>100</mu2>
	          </ode>
		</friction>
	     </surface>
            <material name="">
                <color rgba="0.792156862745098 0.819607843137255 0.933333333333333 1" />
            </material>
        </visual>
        <collision>
            <origin rpy="0 0 0" xyz="0 0 0" />
            <geometry>
                <mesh filename="package://booksink/meshes/booksink_link.STL" />
            </geometry>
        </collision>
    </link>
    <link name="mass_link">
        <visual>
            <geometry>
                <cylinder length="0.1" radius="0.05" />
            </geometry>
            <material name="blue">
                <color rgba="0 0 .8 1" />
            </material>
        </visual>
        <mass value="200" />
        <inertial auto="true" />
    </link>
    <joint name="mass_joint" type="fixed">
        <origin rpy="0.0 0.0 0.0" xyz="0 0 0.1" />
        <parent link="booksink_link" />
        <child link="mass_link" />
    </joint>
   
    <transmission name="shoulder_pan_trans">
        <type>transmission_interface/SimpleTransmission</type>
        <joint name="shoulder_pan_joint">
            <hardwareInterface>hardware_interface/PositionJointInterface</hardwareInterface>
        </joint>
        <actuator name="shoulder_pan_motor">
            <mechanicalReduction>1</mechanicalReduction>
            <hardwareInterface>hardware_interface/PositionJointInterface</hardwareInterface>
        </actuator>
    </transmission>
    <transmission name="shoulder_lift_trans">
        <type>transmission_interface/SimpleTransmission</type>
        <joint name="shoulder_lift_joint">
            <hardwareInterface>hardware_interface/PositionJointInterface</hardwareInterface>
        </joint>
        <actuator name="shoulder_lift_motor">
            <mechanicalReduction>1</mechanicalReduction>
            <hardwareInterface>hardware_interface/PositionJointInterface</hardwareInterface>
        </actuator>
    </transmission>
    <transmission name="elbow_trans">
        <type>transmission_interface/SimpleTransmission</type>
        <joint name="elbow_joint">
            <hardwareInterface>hardware_interface/PositionJointInterface</hardwareInterface>
        </joint>
        <actuator name="elbow_motor">
            <mechanicalReduction>1</mechanicalReduction>
            <hardwareInterface>hardware_interface/PositionJointInterface</hardwareInterface>
        </actuator>
    </transmission>
    <transmission name="wrist_1_trans">
        <type>transmission_interface/SimpleTransmission</type>
        <joint name="wrist_1_joint">
            <hardwareInterface>hardware_interface/PositionJointInterface</hardwareInterface>
        </joint>
        <actuator name="wrist_1_motor">
            <mechanicalReduction>1</mechanicalReduction>
            <hardwareInterface>hardware_interface/PositionJointInterface</hardwareInterface>
        </actuator>
    </transmission>
    <transmission name="wrist_2_trans">
        <type>transmission_interface/SimpleTransmission</type>
        <joint name="wrist_2_joint">
            <hardwareInterface>hardware_interface/PositionJointInterface</hardwareInterface>
        </joint>
        <actuator name="wrist_2_motor">
            <mechanicalReduction>1</mechanicalReduction>
            <hardwareInterface>hardware_interface/PositionJointInterface</hardwareInterface>
        </actuator>
    </transmission>
    <transmission name="wrist_3_trans">
        <type>transmission_interface/SimpleTransmission</type>
        <joint name="wrist_3_joint">
            <hardwareInterface>hardware_interface/PositionJointInterface</hardwareInterface>
        </joint>
        <actuator name="wrist_3_motor">
            <mechanicalReduction>1</mechanicalReduction>
            <hardwareInterface>hardware_interface/PositionJointInterface</hardwareInterface>
        </actuator>
    </transmission>
    <!-- links: main serial chain -->
    <link name="base_link" />
    <link name="base_link_inertia">
        <visual>
            <origin rpy="0 0 3.141592653589793" xyz="0 0 0" />
            <geometry>
                <mesh filename="package://ur_description/meshes/ur5/visual/base.dae" />
            </geometry>
            <material name="LightGrey">
                <color rgba="0.7 0.7 0.7 1.0" />
            </material>
        </visual>
        <collision>
            <origin rpy="0 0 3.141592653589793" xyz="0 0 0" />
            <geometry>
                <mesh filename="package://ur_description/meshes/ur5/collision/base.stl" />
            </geometry>
        </collision>
        <inertial>
            <mass value="4.0" />
            <origin rpy="0 0 0" xyz="0 0 0" />
            <inertia ixx="0.00443333156" ixy="0.0" ixz="0.0" iyy="0.00443333156" iyz="0.0" izz="0.0072" />
        </inertial>
    </link>
    <link name="shoulder_link">
        <visual>
            <origin rpy="0 0 3.141592653589793" xyz="0 0 0" />
            <geometry>
                <mesh filename="package://ur_description/meshes/ur5/visual/shoulder.dae" />
            </geometry>
            <material name="LightGrey">
                <color rgba="0.7 0.7 0.7 1.0" />
            </material>
        </visual>
        <collision>
            <origin rpy="0 0 3.141592653589793" xyz="0 0 0" />
            <geometry>
                <mesh filename="package://ur_description/meshes/ur5/collision/shoulder.stl" />
            </geometry>
        </collision>
        <inertial>
            <mass value="3.7" />
            <origin rpy="0 0 0" xyz="0 0 0" />
            <inertia ixx="0.014972352344389999" ixy="0.0" ixz="0.0" iyy="0.014972352344389999" iyz="0.0" izz="0.01040625" />
        </inertial>
    </link>
    <link name="upper_arm_link">
        <visual>
            <origin rpy="1.5707963267948966 0 -1.5707963267948966" xyz="0 0 0.13585" />
            <geometry>
                <mesh filename="package://ur_description/meshes/ur5/visual/upperarm.dae" />
            </geometry>
            <material name="LightGrey">
                <color rgba="0.7 0.7 0.7 1.0" />
            </material>
        </visual>
        <collision>
            <origin rpy="1.5707963267948966 0 -1.5707963267948966" xyz="0 0 0.13585" />
            <geometry>
                <mesh filename="package://ur_description/meshes/ur5/collision/upperarm.stl" />
            </geometry>
        </collision>
        <inertial>
            <mass value="8.393" />
            <origin rpy="0 1.5707963267948966 0" xyz="-0.2125 0.0 0.136" />
            <inertia ixx="0.1338857818623325" ixy="0.0" ixz="0.0" iyy="0.1338857818623325" iyz="0.0" izz="0.0151074" />
        </inertial>
    </link>
    <link name="forearm_link">
        <visual>
            <origin rpy="1.5707963267948966 0 -1.5707963267948966" xyz="0 0 0.0165" />
            <geometry>
                <mesh filename="package://ur_description/meshes/ur5/visual/forearm.dae" />
            </geometry>
            <material name="LightGrey">
                <color rgba="0.7 0.7 0.7 1.0" />
            </material>
        </visual>
        <collision>
            <origin rpy="1.5707963267948966 0 -1.5707963267948966" xyz="0 0 0.0165" />
            <geometry>
                <mesh filename="package://ur_description/meshes/ur5/collision/forearm.stl" />
            </geometry>
        </collision>
        <inertial>
            <mass value="2.275" />
            <origin rpy="0 1.5707963267948966 0" xyz="-0.196125 0.0 0.0165" />
            <inertia ixx="0.03121679102890359" ixy="0.0" ixz="0.0" iyy="0.03121679102890359" iyz="0.0" izz="0.004095" />
        </inertial>
    </link>
    <link name="wrist_1_link">
        <visual>
            <!-- TODO: Move this to a parameter -->
            <origin rpy="1.5707963267948966 0 0" xyz="0 0 -0.093" />
            <geometry>
                <mesh filename="package://ur_description/meshes/ur5/visual/wrist1.dae" />
            </geometry>
            <material name="LightGrey">
                <color rgba="0.7 0.7 0.7 1.0" />
            </material>
        </visual>
        <collision>
            <origin rpy="1.5707963267948966 0 0" xyz="0 0 -0.093" />
            <geometry>
                <mesh filename="package://ur_description/meshes/ur5/collision/wrist1.stl" />
            </geometry>
        </collision>
        <inertial>
            <mass value="1.219" />
            <origin rpy="0 0 0" xyz="0 0 0" />
            <inertia ixx="0.0020138887777775" ixy="0.0" ixz="0.0" iyy="0.0020138887777775" iyz="0.0" izz="0.0021942" />
        </inertial>
    </link>
    <link name="wrist_2_link">
        <visual>
            <origin rpy="0 0 0" xyz="0 0 -0.095" />
            <geometry>
                <mesh filename="package://ur_description/meshes/ur5/visual/wrist2.dae" />
            </geometry>
            <material name="LightGrey">
                <color rgba="0.7 0.7 0.7 1.0" />
            </material>
        </visual>
        <collision>
            <origin rpy="0 0 0" xyz="0 0 -0.095" />
            <geometry>
                <mesh filename="package://ur_description/meshes/ur5/collision/wrist2.stl" />
            </geometry>
        </collision>
        <inertial>
            <mass value="1.219" />
            <origin rpy="0 0 0" xyz="0 0 0" />
            <inertia ixx="0.0018310388509175" ixy="0.0" ixz="0.0" iyy="0.0018310388509175" iyz="0.0" izz="0.0021942" />
        </inertial>
    </link>
    <link name="wrist_3_link">
        <visual>
            <origin rpy="1.5707963267948966 0 0" xyz="0 0 -0.0818" />
            <geometry>
                <mesh filename="package://ur_description/meshes/ur5/visual/wrist3.dae" />
            </geometry>
            <material name="LightGrey">
                <color rgba="0.7 0.7 0.7 1.0" />
            </material>
        </visual>
        <collision>
            <origin rpy="1.5707963267948966 0 0" xyz="0 0 -0.0818" />
            <geometry>
                <mesh filename="package://ur_description/meshes/ur5/collision/wrist3.stl" />
            </geometry>
        </collision>
        <inertial>
            <mass value="0.1879" />
            <origin rpy="0 0 0" xyz="0.0 0.0 -0.01525" />
            <inertia ixx="8.062472608343e-05" ixy="0.0" ixz="0.0" iyy="8.062472608343e-05" iyz="0.0" izz="0.0001321171875" />
        </inertial>
    </link>
    <!-- joints: main serial chain -->
    <joint name="base_link-base_link_inertia" type="fixed">
        <parent link="base_link" />
        <child link="base_link_inertia" />
        <!-- 'base_link' is REP-103 aligned (so X+ forward), while the internal
           frames of the robot/controller have X+ pointing backwards.
           Use the joint between 'base_link' and 'base_link_inertia' (a dummy
           link/frame) to introduce the necessary rotation over Z (of pi rad).
      -->
        <origin rpy="0 0 3.141592653589793" xyz="0 0 0" />
    </joint>
    <joint name="shoulder_pan_joint" type="revolute">
        <parent link="base_link_inertia" />
        <child link="shoulder_link" />
        <origin rpy="0 0 0" xyz="0 0 0.089159" />
        <axis xyz="0 0 1" />
        <limit effort="150.0" lower="-6.283185307179586" upper="6.283185307179586" velocity="3.141592653589793" />
        <dynamics damping="0" friction="50" />
    </joint>
    <joint name="shoulder_lift_joint" type="revolute">
        <parent link="shoulder_link" />
        <child link="upper_arm_link" />
        <origin rpy="1.570796327 0 0" xyz="0 0 0" />
        <axis xyz="0 0 1" />
        <limit effort="150.0" lower="-6.283185307179586" upper="6.283185307179586" velocity="3.141592653589793" />
        <dynamics damping="0" friction="50" />
    </joint>
    <joint name="elbow_joint" type="revolute">
        <parent link="upper_arm_link" />
        <child link="forearm_link" />
        <origin rpy="0 0 0" xyz="-0.425 0 0" />
        <axis xyz="0 0 1" />
        <limit effort="150.0" lower="-3.141592653589793" upper="3.141592653589793" velocity="3.141592653589793" />
        <dynamics damping="0" friction="50" />
    </joint>
    <joint name="wrist_1_joint" type="revolute">
        <parent link="forearm_link" />
        <child link="wrist_1_link" />
        <origin rpy="0 0 0" xyz="-0.39225 0 0.10915" />
        <axis xyz="0 0 1" />
        <limit effort="28.0" lower="-6.283185307179586" upper="6.283185307179586" velocity="3.141592653589793" />
        <dynamics damping="0" friction="50" />
    </joint>
    <joint name="wrist_2_joint" type="revolute">
        <parent link="wrist_1_link" />
        <child link="wrist_2_link" />
        <origin rpy="1.570796327 0 0" xyz="0 -0.09465 -1.941303950897609e-11" />
        <axis xyz="0 0 1" />
        <limit effort="28.0" lower="-6.283185307179586" upper="6.283185307179586" velocity="3.141592653589793" />
        <dynamics damping="0" friction="50" />
    </joint>
    <joint name="wrist_3_joint" type="revolute">
        <parent link="wrist_2_link" />
        <child link="wrist_3_link" />
        <origin rpy="1.570796326589793 3.141592653589793 3.141592653589793" xyz="0 0.0823 -1.688001216681175e-11" />
        <axis xyz="0 0 1" />
        <limit effort="28.0" lower="-6.283185307179586" upper="6.283185307179586" velocity="3.141592653589793" />
        <dynamics damping="0" friction="50" />
    </joint>
    <!-- ROS-Industrial 'base' frame: base_link to UR 'Base' Coordinates transform -->
    <link name="base" />
    <joint name="base_link-base_fixed_joint" type="fixed">
        <!-- Note the rotation over Z of pi radians: as base_link is REP-103
           aligned (ie: has X+ forward, Y+ left and Z+ up), this is needed
           to correctly align 'base' with the 'Base' coordinate system of
           the UR controller.
      -->
        <origin rpy="0 0 3.141592653589793" xyz="0 0 0" />
        <parent link="base_link" />
        <child link="base" />
    </joint>
    <!-- ROS-Industrial 'flange' frame: attachment point for EEF models -->
    <link name="flange" />
    <joint name="wrist_3-flange" type="fixed">
        <parent link="wrist_3_link" />
        <child link="flange" />
        <origin rpy="0 -1.5707963267948966 -1.5707963267948966" xyz="0 0 0" />
    </joint>
    <!-- ROS-Industrial 'tool0' frame: all-zeros tool frame -->
    <link name="tool0" />
    <joint name="flange-tool0" type="fixed">
        <!-- default toolframe: X+ left, Y+ up, Z+ front -->
        <origin rpy="1.5707963267948966 0 1.5707963267948966" xyz="0 0 0" />
        <parent link="flange" />
        <child link="tool0" />
    </joint>
    <joint name="sink_ur5_joint" type="fixed">
        <origin rpy="0.0 0.0 -1.57" xyz="-0.308 -0.2105 0.875" />
        <parent link="booksink_link" />
        <child link="base_link" />
    </joint>
    <!-- mount the fts to the robot -->
    <joint name="ft300_fix" type="fixed">
        <origin rpy="0 0 0" xyz="0 0 0" />
        <parent link="tool0" />
        <child link="ft300_mounting_plate" />
    </joint>
    <!-- Link representing the FT300 force-torque sensor -->
    <link name="ft300_sensor">
        <inertial>
            <origin rpy="0 0 0" xyz="0 0 -0.017" />
            <mass value="0.300" />
            <inertia ixx="0.000262" ixy="0" ixz="1e-06" iyx="0" iyy="0.000265" iyz="1e-06" izx="-1e-06" izy="1e-06" izz="0.000219" />
        </inertial>
        <visual>
            <origin rpy="0 0 0" xyz="0 0 0" />
            <geometry>
                <mesh filename="package://robotiq_ft_sensor/meshes/visual/robotiq_ft300.STL" />
            </geometry>
            <material name="Robotiq-Black">
                <color rgba="0.2 0.2 0.2 1.0" />
            </material>
        </visual>
        <collision>
            <origin rpy="0 0 0" xyz="0 0 0" />
            <geometry>
                <mesh filename="package://robotiq_ft_sensor/meshes/collision/robotiq_ft300.STL" />
            </geometry>
        </collision>
    </link>
    <!-- Link representing the FT300 mounting plate -->
    <link name="ft300_mounting_plate">
        <visual>
            <origin rpy="0 0 0" xyz="0 0 0" />
            <geometry>
                <mesh filename="package://robotiq_ft_sensor/meshes/visual/mountings/robotiq_ft300-G-062-COUPLING_G-50-4M6-1D6_20181119.STL" />
            </geometry>
            <material name="Robotiq-Grey">
                <color rgba="0.4 0.4 0.4 1.0" />
            </material>
        </visual>
        <collision>
            <origin rpy="0 0 0" xyz="0 0 0" />
            <geometry>
                <mesh filename="package://robotiq_ft_sensor/meshes/collision/mountings/robotiq_ft300-G-062-COUPLING_G-50-4M6-1D6_20181119.STL" />
            </geometry>
        </collision>
        <inertial>
            <mass value="0.1" />
            <origin xyz="0 0 0" rpy="0 0 0" />
            <inertia ixx="0.03" iyy="0.03" izz="0.03" ixy="0.0" ixz="0.0" iyz="0.0" />
        </inertial>
    </link>
    <!-- Connect force sensor with mounting/coupling plate -->
    <joint name="ft300_mounting_plate" type="fixed">
        <origin rpy="0 3.141592653589793 0" xyz="0 0 0.0415" />
        <parent link="ft300_mounting_plate" />
        <child link="ft300_sensor" />
    </joint>
    <!-- FORCE REFERENCE FRAME _______________________________________________________________________________
            As specified in the documentation:
            - The Z axis passes through the center of the depression with positive direction in the tool direction.
            - The X axis traces a symmetric line centered on the connector; the positive direction
                points the opposite way away from the connector.
            - The Y axis uses the right hand thumb rule according to X-Z. -->
    <joint name="measurment_joint" type="fixed">
        <origin rpy="0 3.141592653589793 -1.5707963267948966" xyz="0 0 0" />
        <parent link="ft300_sensor" />
        <child link="robotiq_ft_frame_id" />
    </joint>
    <link name="robotiq_ft_frame_id" />
    <link name="camera_holder_link">
        <inertial>
            <origin rpy="0 0 0" xyz="-0.0411506279575293 0.00967050494261833 0.0398549926423877" />
            <mass value="0.0521202445897232" />
            <inertia ixx="3.8230487702132E-05" ixy="2.26934260877875E-06" ixz="3.27421083069475E-10" iyy="9.02678753746264E-05" iyz="-1.93257602854457E-11" izz="5.35195933007049E-05" />
        </inertial>
        <visual>
            <origin rpy="0 0 0" xyz="0 0 0" />
            <geometry>
                <mesh filename="package://camera_holder/meshes/camera_holder_link.STL" />
            </geometry>
            <material name="">
                <color rgba="0.792156862745098 0.819607843137255 0.933333333333333 1" />
            </material>
        </visual>
        <collision>
            <origin rpy="0 0 0" xyz="0 0 0" />
            <geometry>
                <mesh filename="package://camera_holder/meshes/camera_holder_link.STL" />
            </geometry>
        </collision>
    </link>
    <joint name="camera_holder_joint" type="fixed">
        <parent link="wrist_3_link" />
        <child link="camera_holder_link" />
        <origin rpy="1.5708 0 1.5708" xyz="-0.0395 0 -0.03" />
    </joint>
    <material name="aluminum">
        <color rgba="0.5 0.5 0.5 1" />
    </material>
    <material name="plastic">
        <color rgba="0.1 0.1 0.1 1" />
    </material>
    <!-- camera body, with origin at bottom screw mount -->
    <joint name="camera_joint" type="fixed">
        <origin rpy="-1.5708 0 1.5708" xyz="-0.11 0.026 0.04" />
        <parent link="camera_holder_link" />
        <child link="camera_bottom_screw_frame" />
    </joint>
    <link name="camera_bottom_screw_frame" />
    <joint name="camera_link_joint" type="fixed">
        <origin rpy="0 0 0" xyz="0.010600000000000002 0.0175 0.0125" />
        <parent link="camera_bottom_screw_frame" />
        <child link="camera_link" />
    </joint>
    <link name="camera_link">
        <visual>
            <!-- the mesh origin is at front plate in between the two infrared camera axes -->
            <origin rpy="1.5707963267948966 0 1.5707963267948966" xyz="0.0043 -0.0175 0" />
            <geometry>
                <mesh filename="package://realsense2_description/meshes/d435.dae" />
            </geometry>
        </visual>
        <collision>
            <origin rpy="0 0 0" xyz="0 -0.0175 0" />
            <geometry>
                <box size="0.02505 0.09 0.025" />
            </geometry>
        </collision>
        <inertial>
            <!-- The following are not reliable values, and should not be used for modeling -->
            <mass value="0.072" />
            <origin xyz="0 0 0" rpy="0 0 0" />
            <inertia ixx="0.003881243" ixy="0.0" ixz="0.0" iyy="0.000498940" iyz="0.0" izz="0.003879257" />
        </inertial>
    </link>
     <!-- camera depth joints and links -->
     <joint name="camera_depth_joint" type="fixed">
        <origin rpy="0 0 0" xyz="0 0 0" />
        <parent link="camera_link" />
        <child link="camera_depth_frame" />
    </joint>
    <link name="camera_depth_frame" />
    <joint name="camera_depth_optical_joint" type="fixed">
        <origin rpy="-1.5707963267948966 0 -1.5707963267948966" xyz="0 0 0" />
        <parent link="camera_depth_frame" />
        <child link="camera_depth_optical_frame" />
    </joint>
    <link name="camera_depth_optical_frame" />
    <!-- camera left IR joints and links -->
    <joint name="camera_infra1_joint" type="fixed">
        <origin rpy="0 0 0" xyz="0 0.0 0" />
        <parent link="camera_link" />
        <child link="camera_infra1_frame" />
    </joint>
    <link name="camera_infra1_frame" />
    <joint name="camera_infra1_optical_joint" type="fixed">
        <origin rpy="-1.5707963267948966 0 -1.5707963267948966" xyz="0 0 0" />
        <parent link="camera_infra1_frame" />
        <child link="camera_infra1_optical_frame" />
    </joint>
    <link name="camera_infra1_optical_frame" />
    <!-- camera right IR joints and links -->
    <joint name="camera_infra2_joint" type="fixed">
        <origin rpy="0 0 0" xyz="0 -0.05 0" />
        <parent link="camera_link" />
        <child link="camera_infra2_frame" />
    </joint>
    <link name="camera_infra2_frame" />
    <joint name="camera_infra2_optical_joint" type="fixed">
        <origin rpy="-1.5707963267948966 0 -1.5707963267948966" xyz="0 0 0" />
        <parent link="camera_infra2_frame" />
        <child link="camera_infra2_optical_frame" />
    </joint>
    <link name="camera_infra2_optical_frame" />
    <!-- camera color joints and links -->
    <joint name="camera_color_joint" type="fixed">
        <origin rpy="0 0 0" xyz="0 0.015 0" />
        <parent link="camera_link" />
        <child link="camera_color_frame" />
    </joint>
    <link name="camera_color_frame" />
    <joint name="camera_color_optical_joint" type="fixed">
        <origin rpy="-1.5707963267948966 0 -1.5707963267948966" xyz="0 0 0" />
        <parent link="camera_color_frame" />
        <child link="camera_color_optical_frame" />
    </joint>
    <link name="camera_color_optical_frame" />
    <gazebo reference="camera_link">
        <self_collide>0</self_collide>
        <enable_wind>0</enable_wind>
        <kinematic>0</kinematic>
        <gravity>1</gravity>
        <!--<mu>1</mu>-->
        <mu2>1</mu2>
        <fdir1>0 0 0</fdir1>
        <!--<slip1>0</slip1>
      <slip2>0</slip2>-->
        <kp>1e+13</kp>
        <kd>1</kd>
        <!--<max_vel>0.01</max_vel>
      <min_depth>0</min_depth>-->
        <sensor name="cameracolor" type="camera">
            <camera name="camera">
                <horizontal_fov>1.2112585008840648</horizontal_fov>
                <image>
                    <width>640</width>
                    <height>480</height>
                    <format>RGB_INT8</format>
                </image>
                <clip>
                    <near>0.1</near>
                    <far>100</far>
                </clip>
                <noise>
                    <type>gaussian</type>
                    <mean>0.0</mean>
                    <stddev>0.007</stddev>
                </noise>
            </camera>
            <always_on>1</always_on>
            <update_rate>30</update_rate>
            <visualize>1</visualize>
        </sensor>
        <sensor name="cameraired1" type="camera">
            <camera name="camera">
                <horizontal_fov>1.4870205226991688</horizontal_fov>
                <image>
                    <width>1280</width>
                    <height>720</height>
                    <format>L_INT8</format>
                </image>
                <clip>
                    <near>0.1</near>
                    <far>100</far>
                </clip>
                <noise>
                    <type>gaussian</type>
                    <mean>0.0</mean>
                    <stddev>0.05</stddev>
                </noise>
            </camera>
            <always_on>1</always_on>
            <update_rate>90</update_rate>
            <visualize>0</visualize>
        </sensor>
        <sensor name="cameraired2" type="camera">
            <camera name="camera">
                <horizontal_fov>1.4870205226991688</horizontal_fov>
                <image>
                    <width>1280</width>
                    <height>720</height>
                    <format>L_INT8</format>
                </image>
                <clip>
                    <near>0.1</near>
                    <far>100</far>
                </clip>
                <noise>
                    <type>gaussian</type>
                    <mean>0.0</mean>
                    <stddev>0.05</stddev>
                </noise>
            </camera>
            <always_on>1</always_on>
            <update_rate>90</update_rate>
            <visualize>0</visualize>
        </sensor>
        <sensor name="cameradepth" type="depth">
            <camera name="camera">
                <horizontal_fov>1.4870205226991688</horizontal_fov>
                <image>
                    <width>1280</width>
                    <height>720</height>
                </image>
                <clip>
                    <near>0.1</near>
                    <far>100</far>
                </clip>
                <noise>
                    <type>gaussian</type>
                    <mean>0.0</mean>
                    <stddev>0.100</stddev>
                </noise>
            </camera>
            <always_on>1</always_on>
            <update_rate>90</update_rate>
            <visualize>0</visualize>
        </sensor>
        <plugin name="gazebo_ros_control">
            <robotNamespace>/</robotNamespace>
        </plugin>
    </gazebo>
    <gazebo>
        <plugin filename="librealsense_gazebo_plugin.so" name="camera">
            <prefix>camera</prefix>
            <depthUpdateRate>30.0</depthUpdateRate>
            <colorUpdateRate>30.0</colorUpdateRate>
            <infraredUpdateRate>30.0</infraredUpdateRate>
            <depthTopicName>depth/image_raw</depthTopicName>
            <depthCameraInfoTopicName>depth/camera_info</depthCameraInfoTopicName>
            <colorTopicName>color/image_raw</colorTopicName>
            <colorCameraInfoTopicName>color/camera_info</colorCameraInfoTopicName>
            <infrared1TopicName>infra1/image_raw</infrared1TopicName>
            <infrared1CameraInfoTopicName>infra1/camera_info</infrared1CameraInfoTopicName>
            <infrared2TopicName>infra2/image_raw</infrared2TopicName>
            <infrared2CameraInfoTopicName>infra2/camera_info</infrared2CameraInfoTopicName>
            <colorOpticalframeName>camera_color_optical_frame</colorOpticalframeName>
            <depthOpticalframeName>camera_depth_optical_frame</depthOpticalframeName>
            <infrared1OpticalframeName>camera_left_ir_optical_frame</infrared1OpticalframeName>
            <infrared2OpticalframeName>camera_right_ir_optical_frame</infrared2OpticalframeName>
            <rangeMinDepth>0.2</rangeMinDepth>
            <rangeMaxDepth>10.0</rangeMaxDepth>
            <pointCloud>True</pointCloud>
            <pointCloudTopicName>depth/color/points</pointCloudTopicName>
            <pointCloudCutoff>0.25</pointCloudCutoff>
            <pointCloudCutoffMax>9.0</pointCloudCutoffMax>
        </plugin>
    </gazebo>

    <link name="camera_accel_frame" />
    <link name="camera_accel_optical_frame" />
    <link name="camera_gyro_frame" />
    <link name="camera_gyro_optical_frame" />
    <joint name="camera_accel_joint" type="fixed">
        <origin rpy="0 0 0" xyz="-0.01174 -0.00552 0.0051" />
        <parent link="camera_link" />
        <child link="camera_accel_frame" />
    </joint>
    <joint name="camera_accel_optical_joint" type="fixed">
        <origin rpy="-1.5707963267948966 0 -1.5707963267948966" xyz="0 0 0" />
        <parent link="camera_accel_frame" />
        <child link="camera_accel_optical_frame" />
    </joint>
    <joint name="camera_gyro_joint" type="fixed">
        <origin rpy="0 0 0" xyz="-0.01174 -0.00552 0.0051" />
        <parent link="camera_link" />
        <child link="camera_gyro_frame" />
    </joint>
    <joint name="camera_gyro_optical_joint" type="fixed">
        <origin rpy="-1.5707963267948966 0 -1.5707963267948966" xyz="0 0 0" />
        <parent link="camera_gyro_frame" />
        <child link="camera_gyro_optical_frame" />
    </joint>

    <!-- Mimic joints plugin-->
    <gazebo>
        <plugin filename="libroboticsgroup_upatras_gazebo_mimic_joint_plugin.so" name="mimic_robotiq_140_1">
            <joint>finger_joint</joint>
            <mimicJoint>left_inner_knuckle_joint</mimicJoint>
            <multiplier>-1.0</multiplier>
        </plugin>
        <plugin filename="libroboticsgroup_upatras_gazebo_mimic_joint_plugin.so" name="mimic_robotiq_140_2">
            <joint>finger_joint</joint>
            <mimicJoint>left_inner_finger_joint</mimicJoint>
            <multiplier>1.0</multiplier>
        </plugin>
        <plugin filename="libroboticsgroup_upatras_gazebo_mimic_joint_plugin.so" name="mimic_robotiq_140_3">
            <joint>finger_joint</joint>
            <mimicJoint>right_inner_knuckle_joint</mimicJoint>
            <multiplier>-1.0</multiplier>
        </plugin>
        <plugin filename="libroboticsgroup_upatras_gazebo_mimic_joint_plugin.so" name="mimic_robotiq_140_4">
            <joint>finger_joint</joint>
            <mimicJoint>right_inner_finger_joint</mimicJoint>
            <multiplier>1.0</multiplier>
        </plugin>
        <plugin filename="libroboticsgroup_upatras_gazebo_mimic_joint_plugin.so" name="mimic_robotiq_140_5">
            <joint>finger_joint</joint>
            <mimicJoint>right_outer_knuckle_joint</mimicJoint>
            <multiplier>-1.0</multiplier>
        </plugin>
    </gazebo>
    <link name="robotiq_arg2f_base_link">
        <inertial>
            <origin rpy="0 0 0" xyz="8.625E-08 -4.6583E-06 0.03145" />
            <mass value="0.22652" />
            <inertia ixx="0.00020005" ixy="-4.2442E-10" ixz="-2.9069E-10" iyy="0.00017832" iyz="-3.4402E-08" izz="0.00013478" />
        </inertial>
        <visual>
            <origin rpy="0 0 0" xyz="0 0 0" />
            <geometry>
                <mesh filename="package://robotiq_2f_140_gripper_visualization/meshes/visual/robotiq_arg2f_base_link.stl" />
            </geometry>
            <material name="">
                <color rgba="0.1 0.1 0.1 1" />
            </material>
        </visual>
        <collision>
            <origin rpy="0 0 0" xyz="0 0 0" />
            <geometry>
                <mesh filename="package://robotiq_2f_140_gripper_visualization/meshes/collision/robotiq_arg2f_base_link.stl" />
            </geometry>
        </collision>
    </link>
    <link name="left_outer_knuckle">
        <inertial>
            <origin rpy="0 0 0" xyz="-0.000200000000003065 0.0199435877845359 0.0292245259211331" />
            <mass value="0.00853198276973456" />
            <inertia ixx="2.89328108496468E-06" ixy="-1.57935047237397E-19" ixz="-1.93980378593255E-19" iyy="1.86719750325683E-06" iyz="-1.21858577871576E-06" izz="1.21905238907251E-06" />
        </inertial>
        <visual>
            <origin rpy="0 0 0" xyz="0 0 0" />
            <geometry>
                <mesh filename="package://robotiq_2f_140_gripper_visualization/meshes/visual/robotiq_arg2f_140_outer_knuckle.stl" />
            </geometry>
            <material name="">
                <color rgba="0.792156862745098 0.819607843137255 0.933333333333333 1" />
            </material>
        </visual>
        <collision>
            <origin rpy="0 0 0" xyz="0 0 0" />
            <geometry>
                <mesh filename="package://robotiq_2f_140_gripper_visualization/meshes/collision/robotiq_arg2f_140_outer_knuckle.stl" />
            </geometry>
        </collision>
    </link>
    <link name="left_outer_finger">
        <inertial>
            <origin rpy="0 0 0" xyz="0.00030115855001899 0.0373907951953854 -0.0208027427000385" />
            <mass value="0.022614240507152" />
            <inertia ixx="1.52518312458174E-05" ixy="9.76583423954399E-10" ixz="-5.43838577022588E-10" iyy="6.17694243867776E-06" iyz="6.78636130740228E-06" izz="1.16494917907219E-05" />
        </inertial>
        <visual>
            <origin rpy="0 0 0" xyz="0 0 0" />
            <geometry>
                <mesh filename="package://robotiq_2f_140_gripper_visualization/meshes/visual/robotiq_arg2f_140_outer_finger.stl" />
            </geometry>
            <material name="">
                <color rgba="0.1 0.1 0.1 1" />
            </material>
        </visual>
        <collision>
            <origin rpy="0 0 0" xyz="0 0 0" />
            <geometry>
                <mesh filename="package://robotiq_2f_140_gripper_visualization/meshes/collision/robotiq_arg2f_140_outer_finger.stl" />
            </geometry>
        </collision>
    </link>
    <link name="left_inner_finger">
        <inertial>
            <origin rpy="0 0 0" xyz="0.000299999999999317 0.0160078233491243 -0.0136945669206257" />
            <mass value="0.0104003125914103" />
            <inertia ixx="2.71909453810972E-06" ixy="1.35402465472579E-21" ixz="-7.1817349065269E-22" iyy="7.69100314106116E-07" iyz="6.74715432769696E-07" izz="2.30315190420171E-06" />
        </inertial>
        <visual>
            <origin rpy="0 0 0" xyz="0 0 0" />
            <geometry>
                <mesh filename="package://robotiq_2f_140_gripper_visualization/meshes/visual/robotiq_arg2f_140_inner_finger.stl" />
            </geometry>
            <material name="">
                <color rgba="0.1 0.1 0.1 1" />
            </material>
        </visual>
        <collision>
            <origin rpy="0 0 0" xyz="0 0 0" />
            <geometry>
                <mesh filename="package://robotiq_2f_140_gripper_visualization/meshes/collision/robotiq_arg2f_140_inner_finger.stl" />
            </geometry>
        </collision>
    </link>
    <link name="left_inner_finger_pad">
        <visual>
            <origin rpy="0 0 0" xyz="0 0 0" />
            <geometry>
                <box size="0.027 0.065 0.0075" />
            </geometry>
            <material name="">
                <color rgba="0.9 0.9 0.9 1" />
            </material>
        </visual>
        <collision>
            <origin rpy="0 0 0" xyz="0 0 0" />
            <geometry>
                <box size="0.03 0.07 0.0075" />
            </geometry>
            <material name="">
                <color rgba="0.9 0.0 0.0 1" />
            </material>
        </collision>
        <inertial>
            <mass value="0.1" />
            <origin xyz="0 0 0" rpy="0 0 0" />
            <inertia ixx="0.0" iyy="0.0" izz="0.0" ixy="0.0" ixz="0.0" iyz="0.0" />
        </inertial>
    </link>
    <link name="left_inner_knuckle">
        <inertial>
            <origin rpy="0 0 0" xyz="0.000123011831763771 0.0507850843201817 0.00103968640075166" />
            <mass value="0.0271177346495152" />
            <inertia ixx="2.61910379223783E-05" ixy="-2.43616858946494E-07" ixz="-6.37789906117123E-09" iyy="2.8270243746167E-06" iyz="-5.37200748039765E-07" izz="2.83695868220296E-05" />
        </inertial>
        <visual>
            <origin rpy="0 0 0" xyz="0 0 0" />
            <geometry>
                <mesh filename="package://robotiq_2f_140_gripper_visualization/meshes/visual/robotiq_arg2f_140_inner_knuckle.stl" />
            </geometry>
            <material name="">
                <color rgba="0.1 0.1 0.1 1" />
            </material>
        </visual>
        <collision>
            <origin rpy="0 0 0" xyz="0 0 0" />
            <geometry>
                <mesh filename="package://robotiq_2f_140_gripper_visualization/meshes/collision/robotiq_arg2f_140_inner_knuckle.stl" />
            </geometry>
        </collision>
    </link>
    <link name="right_outer_knuckle">
        <inertial>
            <origin rpy="0 0 0" xyz="-0.000200000000003065 0.0199435877845359 0.0292245259211331" />
            <mass value="0.00853198276973456" />
            <inertia ixx="2.89328108496468E-06" ixy="-1.57935047237397E-19" ixz="-1.93980378593255E-19" iyy="1.86719750325683E-06" iyz="-1.21858577871576E-06" izz="1.21905238907251E-06" />
        </inertial>
        <visual>
            <origin rpy="0 0 0" xyz="0 0 0" />
            <geometry>
                <mesh filename="package://robotiq_2f_140_gripper_visualization/meshes/visual/robotiq_arg2f_140_outer_knuckle.stl" />
            </geometry>
            <material name="">
                <color rgba="0.792156862745098 0.819607843137255 0.933333333333333 1" />
            </material>
        </visual>
        <collision>
            <origin rpy="0 0 0" xyz="0 0 0" />
            <geometry>
                <mesh filename="package://robotiq_2f_140_gripper_visualization/meshes/collision/robotiq_arg2f_140_outer_knuckle.stl" />
            </geometry>
        </collision>
    </link>
    <link name="right_outer_finger">
        <inertial>
            <origin rpy="0 0 0" xyz="0.00030115855001899 0.0373907951953854 -0.0208027427000385" />
            <mass value="0.022614240507152" />
            <inertia ixx="1.52518312458174E-05" ixy="9.76583423954399E-10" ixz="-5.43838577022588E-10" iyy="6.17694243867776E-06" iyz="6.78636130740228E-06" izz="1.16494917907219E-05" />
        </inertial>
        <visual>
            <origin rpy="0 0 0" xyz="0 0 0" />
            <geometry>
                <mesh filename="package://robotiq_2f_140_gripper_visualization/meshes/visual/robotiq_arg2f_140_outer_finger.stl" />
            </geometry>
            <material name="">
                <color rgba="0.1 0.1 0.1 1" />
            </material>
        </visual>
        <collision>
            <origin rpy="0 0 0" xyz="0 0 0" />
            <geometry>
                <mesh filename="package://robotiq_2f_140_gripper_visualization/meshes/collision/robotiq_arg2f_140_outer_finger.stl" />
            </geometry>
        </collision>
    </link>
    <link name="right_inner_finger">
        <inertial>
            <origin rpy="0 0 0" xyz="0.000299999999999317 0.0160078233491243 -0.0136945669206257" />
            <mass value="0.0104003125914103" />
            <inertia ixx="2.71909453810972E-06" ixy="1.35402465472579E-21" ixz="-7.1817349065269E-22" iyy="7.69100314106116E-07" iyz="6.74715432769696E-07" izz="2.30315190420171E-06" />
        </inertial>
        <visual>
            <origin rpy="0 0 0" xyz="0 0 0" />
            <geometry>
                <mesh filename="package://robotiq_2f_140_gripper_visualization/meshes/visual/robotiq_arg2f_140_inner_finger.stl" />
            </geometry>
            <material name="">
                <color rgba="0.1 0.1 0.1 1" />
            </material>
        </visual>
        <collision>
            <origin rpy="0 0 0" xyz="0 0 0" />
            <geometry>
                <mesh filename="package://robotiq_2f_140_gripper_visualization/meshes/collision/robotiq_arg2f_140_inner_finger.stl" />
            </geometry>
        </collision>
    </link>
    <link name="right_inner_finger_pad">
        <visual>
            <origin rpy="0 0 0" xyz="0 0 0" />
            <geometry>
                <box size="0.027 0.065 0.0075" />
            </geometry>
            <material name="">
                <color rgba="0.9 0.9 0.9 1" />
            </material>
        </visual>
        <collision>
            <origin rpy="0 0 0" xyz="0 0 0" />
            <geometry>
                <box size="0.03 0.07 0.0075" />
            </geometry>
            <material name="">
                <color rgba="0.9 0.0 0.0 1" />
            </material>
        </collision>
        <inertial>
            <mass value="0.1" />
            <origin xyz="0 0 0" rpy="0 0 0" />
            <inertia ixx="0.0" iyy="0.0" izz="0.0" ixy="0.0" ixz="0.0" iyz="0.0" />
        </inertial>
    </link>
    <link name="right_inner_knuckle">
        <inertial>
            <origin rpy="0 0 0" xyz="0.000123011831763771 0.0507850843201817 0.00103968640075166" />
            <mass value="0.0271177346495152" />
            <inertia ixx="2.61910379223783E-05" ixy="-2.43616858946494E-07" ixz="-6.37789906117123E-09" iyy="2.8270243746167E-06" iyz="-5.37200748039765E-07" izz="2.83695868220296E-05" />
        </inertial>
        <visual>
            <origin rpy="0 0 0" xyz="0 0 0" />
            <geometry>
                <mesh filename="package://robotiq_2f_140_gripper_visualization/meshes/visual/robotiq_arg2f_140_inner_knuckle.stl" />
            </geometry>
            <material name="">
                <color rgba="0.1 0.1 0.1 1" />
            </material>
        </visual>
        <collision>
            <origin rpy="0 0 0" xyz="0 0 0" />
            <geometry>
                <mesh filename="package://robotiq_2f_140_gripper_visualization/meshes/collision/robotiq_arg2f_140_inner_knuckle.stl" />
            </geometry>
        </collision>
    </link>
    <joint name="finger_joint" type="revolute">
        <origin rpy="2.2957963267948966 0 0" xyz="0 -0.030601 0.054905" />
        <parent link="robotiq_arg2f_base_link" />
        <child link="left_outer_knuckle" />
        <axis xyz="-1 0 0" />
        <limit effort="1000" lower="0" upper="0.7" velocity="2.0" />
    </joint>
    <joint name="left_outer_finger_joint" type="fixed">
        <origin rpy="0 0 0" xyz="0 0.01821998610742 0.0260018192872234" />
        <parent link="left_outer_knuckle" />
        <child link="left_outer_finger" />
        <axis xyz="1 0 0" />
    </joint>
    <joint name="left_inner_knuckle_joint" type="revolute">
        <origin rpy="2.2957963267948966 0 0.0" xyz="0 -0.0127 0.06142" />
        <parent link="robotiq_arg2f_base_link" />
        <child link="left_inner_knuckle" />
        <axis xyz="1 0 0" />
        <limit effort="1000" lower="-0.8757" upper="0.8757" velocity="2.0" />
        <mimic joint="finger_joint" multiplier="-1" offset="0" />
    </joint>
    <joint name="left_inner_finger_joint" type="revolute">
        <origin rpy="-0.725 0 0" xyz="0 0.0817554015893473 -0.0282203446692936" />
        <parent link="left_outer_finger" />
        <child link="left_inner_finger" />
        <axis xyz="1 0 0" />
        <limit effort="1000" lower="-0.8757" upper="0.8757" velocity="2.0" />
        <mimic joint="finger_joint" multiplier="1" offset="0" />
    </joint>
    <joint name="left_inner_finger_pad_joint" type="fixed">
        <origin rpy="0 0 0" xyz="0 0.0457554015893473 -0.0272203446692936" />
        <parent link="left_inner_finger" />
        <child link="left_inner_finger_pad" />
        <axis xyz="0 0 1" />
    </joint>
    <joint name="right_outer_knuckle_joint" type="revolute">
        <origin rpy="2.2957963267948966 0 3.141592653589793" xyz="0 0.030601 0.054905" />
        <parent link="robotiq_arg2f_base_link" />
        <child link="right_outer_knuckle" />
        <axis xyz="1 0 0" />
        <limit effort="1000" lower="-0.725" upper="0.725" velocity="2.0" />
        <mimic joint="finger_joint" multiplier="-1" offset="0" />
    </joint>
    <joint name="right_outer_finger_joint" type="fixed">
        <origin rpy="0 0 0" xyz="0 0.01821998610742 0.0260018192872234" />
        <parent link="right_outer_knuckle" />
        <child link="right_outer_finger" />
        <axis xyz="1 0 0" />
    </joint>
    <joint name="right_inner_knuckle_joint" type="revolute">
        <origin rpy="2.2957963267948966 0 -3.141592653589793" xyz="0 0.0127 0.06142" />
        <parent link="robotiq_arg2f_base_link" />
        <child link="right_inner_knuckle" />
        <axis xyz="1 0 0" />
        <limit effort="1000" lower="-0.8757" upper="0.8757" velocity="2.0" />
        <mimic joint="finger_joint" multiplier="-1" offset="0" />
    </joint>
    <joint name="right_inner_finger_joint" type="revolute">
        <origin rpy="-0.725 0 0" xyz="0 0.0817554015893473 -0.0282203446692936" />
        <parent link="right_outer_finger" />
        <child link="right_inner_finger" />
        <axis xyz="1 0 0" />
        <limit effort="1000" lower="-0.8757" upper="0.8757" velocity="2.0" />
        <mimic joint="finger_joint" multiplier="1" offset="0" />
    </joint>
    <joint name="right_inner_finger_pad_joint" type="fixed">
        <origin rpy="0 0 0" xyz="0 0.0457554015893473 -0.0272203446692936" />
        <parent link="right_inner_finger" />
        <child link="right_inner_finger_pad" />
        <axis xyz="0 0 1" />
    </joint>
    <transmission name="finger_joint_trans">
        <type>transmission_interface/SimpleTransmission</type>
        <joint name="finger_joint">
            <hardwareInterface>EffortJointInterface</hardwareInterface>
        </joint>
        <actuator name="finger_joint_motor">
            <mechanicalReduction>1</mechanicalReduction>
            <hardwareInterface>hardware_interface/EffortJointInterface</hardwareInterface>
        </actuator>
    </transmission>
    <joint name="ft_gripper_joint" type="fixed">
        <parent link="robotiq_ft_frame_id" />
        <child link="robotiq_arg2f_base_link" />
        <origin rpy="0 0 0" xyz="0 0 0" />
    </joint>
    <gazebo>
        <plugin filename="libgazebo_ros_control.so" name="gazebo_ros_control">
            <robotNamespace>/</robotNamespace>
        </plugin>
    </gazebo>
    <transmission name="trans_left_inner_knuckle_joint">
        <type>transmission_interface/SimpleTransmission</type>
        <joint name="left_inner_knuckle_joint">
            <hardwareInterface>hardware_interface/EffortJointInterface</hardwareInterface>
        </joint>
        <actuator name="left_inner_knuckle_joint_motor">
            <hardwareInterface>hardware_interface/EffortJointInterface</hardwareInterface>
            <mechanicalReduction>1</mechanicalReduction>
        </actuator>
    </transmission>
    <transmission name="trans_left_inner_finger_joint">
        <type>transmission_interface/SimpleTransmission</type>
        <joint name="left_inner_finger_joint">
            <hardwareInterface>hardware_interface/EffortJointInterface</hardwareInterface>
        </joint>
        <actuator name="left_inner_finger_joint_motor">
            <hardwareInterface>hardware_interface/EffortJointInterface</hardwareInterface>
            <mechanicalReduction>1</mechanicalReduction>
        </actuator>
    </transmission>
    <transmission name="trans_right_outer_knuckle_joint">
        <type>transmission_interface/SimpleTransmission</type>
        <joint name="right_outer_knuckle_joint">
            <hardwareInterface>hardware_interface/EffortJointInterface</hardwareInterface>
        </joint>
        <actuator name="right_outer_knuckle_joint_motor">
            <hardwareInterface>hardware_interface/EffortJointInterface</hardwareInterface>
            <mechanicalReduction>1</mechanicalReduction>
        </actuator>
    </transmission>
    <transmission name="trans_right_inner_knuckle_joint">
        <type>transmission_interface/SimpleTransmission</type>
        <joint name="right_inner_knuckle_joint">
            <hardwareInterface>hardware_interface/EffortJointInterface</hardwareInterface>
        </joint>
        <actuator name="right_inner_knuckle_joint_motor">
            <hardwareInterface>hardware_interface/EffortJointInterface</hardwareInterface>
            <mechanicalReduction>1</mechanicalReduction>
        </actuator>
    </transmission>
    <transmission name="trans_right_inner_finger_joint">
        <type>transmission_interface/SimpleTransmission</type>
        <joint name="right_inner_finger_joint">
            <hardwareInterface>hardware_interface/EffortJointInterface</hardwareInterface>
        </joint>
        <actuator name="right_inner_finger_joint_motor">
            <hardwareInterface>hardware_interface/EffortJointInterface</hardwareInterface>
            <mechanicalReduction>1</mechanicalReduction>
        </actuator>
    </transmission>
</robot>
